Workbook

Sheet Model>>>
C4: Norwegian Cruise Line Holdings
C5: Ticker: NCLH (NYSE)
C6: Date: 10/2/2026
C7: Recommendation: Short, 6-12 months
C9: Key outputs (selected case, DCF!C9)
C10: Current price | I10: =DCF!I2 -> 15.05
C11: Value per share, EV / EBITDA | I11: =DCF!L34 -> 10.833978
C12: Probability-weighted value | I12: =DCF!G44 -> 11.964428
C13: Return to probability-weighted value | I13: =DCF!G45 -> -0.20502142
C14: DCF cross-check value | I14: =DCF!L46 -> 8.1076995
C15: FY2027E net yield growth | I15: ='Operating Model'!I32 -> -0.0072773132
C16: FY2027E Adjusted EBITDA ($mm) | I16: ='Operating Model'!I52 -> 2472.3891
C17: Street-implied FY2027E EBITDA ($mm) | I17: =Consensus!C57 -> 2693.22
C18: FY2027E Adjusted EPS | I18: ='Operating Model'!I63 -> 0.95137614
C19: Consensus FY2027E EPS (Zacks / Yahoo) | I19: =Consensus!D8 -> 1.46
I20: =Consensus!D7 -> 1.67
C21: Price-implied steady-state EBITDA at 9% ($mm) | I21: =DCF!E31 -> 3038.9729
C22: EBITDA the average target requires ($mm) | I22: =Consensus!C67 -> 2912.6059
C23: Sept 30 deposits forecast ($mm) | I23: =Deposits!C70 -> 2940.2197
C24: KPI 1: 1H27 ticket price y/y, consensus case / ours | H24: =AVERAGE('Net Yield Build'!N24:O24) -> -0.0108108 | I24: =AVERAGE('Net Yield Build'!N51:O51) -> -0.026071794
C25: KPI 2: 2027 occupancy, consensus case / ours | H25: ='Net Yield Build'!U20 -> 1.0306424 | I25: ='Net Yield Build'!U47 -> 1.0206424
C27: Formatting
C28: Blue: hard-coded data from filings and public sources
C29: Blue on gray: forecast assumptions and drivers
C30: Black: formulas
C31: Green: links to other sheets
C33: Sheets
C34: Thesis to KPIs | E34: Start here: data -> KPI -> model -> consensus, with dated checks
C35: DCF | E35: Valuation: case switch (C9), WACC, reverse DCF, EV/EBITDA, DCF cross-check, scenarios, sensitivity
C36: Model vs Consensus / Bridge Build | E36: Model vs. consensus; live 2027 EBITDA bridge, one step per KPI
C37: Operating Model | E37: Annual model FY2024A-FY2030E: capacity, net yield, revenue, costs, P&L, cash flow, ROIC
C38: Net Yield Build | E38: Quarterly net yield for the three cases; KPI rows 24 / 51 / 78 (price) and 13 / 40 / 67 (occupancy)
C39: KPI 1 Price Build | E39: Thesis 1: fare cuts on unsold cabins by brand and region -> ticket price per passenger day
C40: KPI 2 Booking Build | E40: Thesis 2: booking shortfall from deposits -> occupancy and late discounts; price-guarantee claims
C41: Fleet Build / Fleet Qtr Build | E41: Ship-level berths; ship x quarter capacity days (504 rows) for quarterly capacity growth
C42: Consensus | E42: Annual and quarterly consensus, ratings, targets, guidance, decoding the target
C43: Quarterly (A) / Income / Cash Flow / Balance | E43: Historical results: 8-K releases and SEC XBRL
C44: Fare Panel / Deposits | E44: Raw fare panel (4,783 itineraries, summarized) and the deposit indicator (back-test, peers, Nov 4 forecast)
C45: Factor & Positioning / Multiple vs Net Yield | E45: Return decomposition, news days, oil test, short interest; multiple vs. net yield
C46: Exhibit Data | E46: Data behind the memo charts

Sheet Thesis to KPIs
B2: Thesis to KPIs: what the alternative data shows, which model inputs it moves, and where we differ from consensus
B3: Net yield = occupancy x net revenue per passenger day. Our base case differs from the consensus case on two KPIs: ticket price per passenger day (KPI 1) and occupancy (KPI 2). Onboard spend, unit costs and fuel also differ; they are listed separately.
B5: A. FY2027: consensus case vs. our base case | C5: Consensus case | D5: Base case | E5: Difference
B6: Occupancy | C6: ='Net Yield Build'!U20 -> 1.0306424 | D6: ='Net Yield Build'!U47 -> 1.0206424 | E6: =(D6-C6)*100 -> -1
B7: KPI 1 input: ticket revenue per passenger day ($) | C7: ='Net Yield Build'!U25 -> 248.40382 | D7: ='Net Yield Build'!U52 -> 243.98634 | E7: =D7/C7-1 -> -0.017783446
B8: Onboard revenue per passenger day ($) | C8: ='Net Yield Build'!U26 -> 131.44647 | D8: ='Net Yield Build'!U53 -> 129.54003 | E8: =D8/C8-1 -> -0.014503524
B9: Net revenue per passenger day ($) | C9: ='Net Yield Build'!U29 -> 283.89472 | D9: ='Net Yield Build'!U56 -> 279.17896 | E9: =D9/C9-1 -> -0.016610973
B10: Net yield ($ per capacity day) | C10: ='Net Yield Build'!U30 -> 292.59394 | D10: ='Net Yield Build'!U57 -> 284.94188 | E10: =D10/C10-1 -> -0.026152488
B11: Net yield growth y/y | C11: ='Net Yield Build'!U31 -> 0.015702552 | D11: ='Net Yield Build'!U58 -> -0.0072773132 | E11: =(D11-C11)*100 -> -2.2979866
B12: Adjusted EBITDA ($mm) | C12: =DCF!E41 -> 2787.034 | D12: =DCF!E42 -> 2472.3891 | E12: =D12/C12-1 -> -0.11289598
B14: B. The two KPIs by quarter | C14: 3Q26E | D14: 4Q26E | E14: 1Q27E | F14: 2Q27E | G14: 3Q27E | H14: 4Q27E
B15: KPI 1: like-for-like ticket price y/y, consensus case | C15: ='Net Yield Build'!L24 -> -0.0995 | D15: ='Net Yield Build'!M24 -> -0.0603 | E15: ='Net Yield Build'!N24 -> -0.013559834 | F15: ='Net Yield Build'!O24 -> -0.0080617665 | G15: ='Net Yield Build'!P24 -> 0.0039092903 | H15: ='Net Yield Build'!Q24 -> 0.0029699256
B16: KPI 1: ours | C16: ='Net Yield Build'!L51 -> -0.1055 | D16: ='Net Yield Build'!M51 -> -0.0762 | E16: ='Net Yield Build'!N51 -> -0.028407702 | F16: ='Net Yield Build'!O51 -> -0.023735886 | G16: ='Net Yield Build'!P51 -> -0.0044150741 | H16: ='Net Yield Build'!Q51 -> -0.0076694521
B17: of which Thesis 1 (fare cuts on unsold cabins) | C17: ='Net Yield Build'!L42 -> 0 | D17: ='Net Yield Build'!M42 -> -0.032896144 | E17: ='Net Yield Build'!N42 -> -0.033407702 | F17: ='Net Yield Build'!O42 -> -0.028735886 | G17: ='Net Yield Build'!P42 -> -0.0028358453 | H17: ='Net Yield Build'!Q42 -> -0.0060902232
B18: of which Thesis 2 (late discounts on the shortfall) | C18: ='Net Yield Build'!L44 -> 0 | D18: ='Net Yield Build'!M44 -> 0 | E18: ='Net Yield Build'!N44 -> 0 | F18: ='Net Yield Build'!O44 -> 0 | G18: ='Net Yield Build'!P44 -> -0.0065792288 | H18: ='Net Yield Build'!Q44 -> -0.0065792288
B19: KPI 2: occupancy change y/y (pts), consensus case | C19: ='Net Yield Build'!L13 -> -2.4 | D19: ='Net Yield Build'!M13 -> -2.8 | E19: ='Net Yield Build'!N13 -> -1 | F19: ='Net Yield Build'!O13 -> 0.5 | G19: ='Net Yield Build'!P13 -> 1.5 | H19: ='Net Yield Build'!Q13 -> 2
B20: KPI 2: ours | C20: ='Net Yield Build'!L40 -> -2.4 | D20: ='Net Yield Build'!M40 -> -2.8 | E20: ='Net Yield Build'!N40 -> -2 | F20: ='Net Yield Build'!O40 -> -0.5 | G20: ='Net Yield Build'!P40 -> 0.5 | H20: ='Net Yield Build'!Q40 -> 1
B21: Net yield y/y, consensus case | C21: ='Net Yield Build'!L31 -> -0.079971158 | D21: ='Net Yield Build'!M31 -> -0.059984861 | E21: ='Net Yield Build'!N31 -> -0.010613405 | F21: ='Net Yield Build'!O31 -> 0.007404509 | G21: ='Net Yield Build'!P31 -> 0.028777065 | H21: ='Net Yield Build'!Q31 -> 0.037263476
B22: Net yield y/y, ours | C22: ='Net Yield Build'!L58 -> -0.084022341 | D22: ='Net Yield Build'!M58 -> -0.070006965 | E22: ='Net Yield Build'!N58 -> -0.034691082 | F22: ='Net Yield Build'!O58 -> -0.017589168 | G22: ='Net Yield Build'!P58 -> 0.0085040694 | H22: ='Net Yield Build'!Q58 -> 0.014772734
B24: C. Each thesis, from the data to the model
B25: Thesis | C25: What the data shows | D25: What it implies | E25: KPI it moves | F25: Consensus case | G25: Ours | H25: 2027 EBITDA ($mm)
B26: Thesis 1: NCL is cutting price to fill Caribbean ships because it is losing share there | C26: ="1H27 Caribbean fares "&TEXT('KPI 1 Price Build'!F16,"0.0%")&" vs. peers "&TEXT('KPI 1 Price Build'!F19,"0.0%")&"; NCL elsewhere "&TEXT('KPI 1 Price Build'!F17,"0.0%") -> 1H27 Caribbean fares -14.5% vs. peers -0.5%; NCL elsewhere -2.8% | D26: Cuts hit the cabins NCL still has to sell for 1H27 | E26: KPI 1: 1H27 ticket price | F26: =AVERAGE('Net Yield Build'!N24:O24) -> -0.0108108 | G26: =AVERAGE('Net Yield Build'!N51:O51) -> -0.026071794 | H26: ='Model vs Consensus'!C26 -> -43.523693
B27: Thesis 2: the price guarantee keeps guests from booking early | C27: ="Deposits per future berth-day "&TEXT(Deposits!F26,"0.0%")&" y/y; 7th straight decline" -> Deposits per future berth-day -8.3% y/y; 7th straight decline | D27: A booking shortfall NCL fills late at a discount | E27: KPI 1: 2H27 ticket price | F27: =AVERAGE('Net Yield Build'!P24:Q24) -> 0.0034396079 | G27: =AVERAGE('Net Yield Build'!P51:Q51) -> -0.0060422631 | H27: ='Model vs Consensus'!C27 -> -17.090892
B28: Thesis 2 (continued) | C28: ="Occupancy fell "&TEXT(-'KPI 2 Booking Build'!D17,"0.0")&" pts in 2Q26 with the indicator at "&TEXT('KPI 2 Booking Build'!D18,"0.0%") -> Occupancy fell 1.5 pts in 2Q26 with the indicator at -6.1% | D28: Part of the shortfall sails empty | E28: KPI 2: 2027 occupancy | F28: ='Net Yield Build'!U20 -> 1.0306424 | G28: ='Net Yield Build'!U47 -> 1.0206424 | H28: ='Model vs Consensus'!C28 -> -76.058523
B30: Other differences (not part of either thesis)
B31: Onboard spend growth per passenger day, 2027 | C31: 2025: -0.3%; 1H26: +1.0% (Quarterly (A)) | F31: ='Net Yield Build'!N18 -> 0.035 | G31: ='Net Yield Build'!N45 -> 0.02 | H31: ='Model vs Consensus'!C29 -> -41.546117
B32: Unit costs ex fuel per capacity day, 2027 y/y | C32: 1H26 about flat; 3Q26 guide -0.9%; $225M savings plan | F32: ='Operating Model'!I11 -> -0.005 | G32: ='Operating Model'!I12 -> 0.01 | H32: ='Model vs Consensus'!C30 -> -107.10628
B33: Fuel price per ton, net of hedges ($) | C33: 2026 guide $780; Brent +63% y/y | F33: ='Operating Model'!I16 -> 760 | G33: ='Operating Model'!I17 -> 800
B34: Unit costs and fuel share one bridge step (Model vs Consensus row 30).
B36: D. What each KPI is worth (base case, 2027)
B37: 1 pt of ticket price per passenger day: EBITDA ($mm) | C37: ='Net Yield Build'!U59*(1-'Net Yield Build'!U54)*0.01 -> 49.066202 | D37: per share: | E37: =C37*$C$39 -> 0.88788621
B38: 1 pt of occupancy: EBITDA ($mm) | C38: ='Net Yield Build'!U46*0.01*'Net Yield Build'!U56 -> 75.71873 | D38: per share: | E38: =C38*$C$39 -> 1.3701818
B39: Value per share of $1M of 2027 EBITDA (at today's multiple) | C39: =DCF!F25/DCF!L33 -> 0.018095678
B40: Value per share on the two theses alone (consensus-case onboard, costs and fuel) | C40: =((DCF!E42-'Model vs Consensus'!C29-'Model vs Consensus'!C30)*DCF!F25-DCF!F22)/DCF!L33 -> 13.523944 | D40: =C40/DCF!I2-1 -> -0.1013991
B42: E. Dated checks: when each KPI gets tested
B43: Nov 4, 2026: 3Q26 10-Q | C43: Sept 30 advance ticket sales vs. our $2.94B (KPI 2 shortfall) | G43: ="Below "&TEXT('KPI 2 Booking Build'!D58,"$#,##0")&"M supports; at or above "&TEXT('KPI 2 Booking Build'!D59,"$#,##0")&"M we cover" -> Below $2,970M supports; at or above $3,110M we cover
B44: Late Feb 2027: first 2027 guide | C44: Net yield guide vs. the consensus case (KPI 1 and KPI 2) | G44: ="At or below flat supports; consensus case "&TEXT('Net Yield Build'!U31,"+0.0%") -> At or below flat supports; consensus case +1.6%
B45: Monthly: fare panel re-run | C45: 1H27 Caribbean cuts on unsold cabins (KPI 1) | G45: Cuts back near peers would undo Thesis 1
B46: May 2027: 1Q27 results | C46: Reported ticket revenue per passenger day and occupancy | G46: ="Ours: occupancy "&TEXT('Net Yield Build'!N47,"0.0%")&", ticket price "&TEXT('Net Yield Build'!N51,"0.0%") -> Ours: occupancy 101.8%, ticket price -2.8%
B48: Green = links; black = formulas. Every number on this sheet comes from the KPI builds, the Net Yield Build or the DCF.

Sheet DCF
B2: Norwegian Cruise Line Holdings | G2: Current Price | I2: 15.05
B4: Valuation
B5: $mm except per-share data
B7: Case Selection
B9: Selected Case | C9: 2
B11: Bull case (Street-like) | C11: 1
B12: Base case (our view) | C12: 2
B13: Bear case | C13: 3
B15: Market data | H15: WACC
B16: Share price | F16: =I2 -> 15.05 | H16: Risk-free rate (10-year Treasury) | L16: 0.042
B17: Basic shares outstanding (M) | F17: 459.19 | H17: Beta (levered) | L17: 1.8
B18: Market capitalization | F18: =F16*F17 -> 6910.8095 | H18: Equity risk premium | L18: 0.05
B19: Net debt (Jun 30, 2026) | F19: ='Quarterly (A)'!J40 -> 14800 | H19: Cost of equity | L19: =L16+L17*L18 -> 0.132
B20: Enterprise value | F20: =F18+F19 -> 21710.809 | H20: Pre-tax cost of debt | L20: 0.0725
B21: Net debt at YE2026E (model, selected case) | F21: ='Operating Model'!H88 -> 15883.244 | H21: Tax rate | L21: 0.02
B22: Net debt at YE2026E used in valuation | F22: 15800 | H22: Equity weight | L22: =F18/(F18+F19) -> 0.31831192
B23: Forward EV (market cap + YE2026E net debt) | F23: =F18+F22 -> 22710.809 | H23: Debt weight | L23: =1-L22 -> 0.68168808
B24: Street-implied FY2027E EBITDA | F24: =Consensus!C57 -> 2693.22 | H24: WACC | L24: =L19*L22+L20*(1-L21)*L23 -> 0.090451112
B25: Market EV / FY2027E EBITDA (Street) | F25: =F23/F24 -> 8.4325861
B27: Price-implied expectations (reverse DCF) | H27: Primary valuation: EV / FY2027E EBITDA
B28: Cost of capital | C28: 0.08 | D28: 0.085 | E28: 0.09 | F28: =L24 -> 0.090451112 | H28: FY2027E Adjusted EBITDA (selected case) | L28: ='Operating Model'!I52 -> 2472.3891
B29: Enterprise value (today) | C29: =$F$20 -> 21710.809 | D29: =$F$20 -> 21710.809 | E29: =$F$20 -> 21710.809 | F29: =$F$20 -> 21710.809 | H29: Target EV / EBITDA | L29: =CHOOSE($C$9,$L$36,$F$25,$F$25) -> 8.4325861
B30: (+) Steady-state D&A (2026E guide) | C30: ='Operating Model'!$H$54 -> 1085 | D30: ='Operating Model'!$H$54 -> 1085 | E30: ='Operating Model'!$H$54 -> 1085 | F30: ='Operating Model'!$H$54 -> 1085 | H30: Implied enterprise value | L30: =L28*L29 -> 20848.634
B31: Implied steady-state EBITDA | C31: =C29*C28+C30 -> 2821.8648 | D31: =D29*D28+D30 -> 2930.4188 | E31: =E29*E28+E30 -> 3038.9729 | F31: =F29*F28+F30 -> 3048.7669 | H31: (-) Net debt at YE2026E | L31: =$F$22 -> 15800
B32: 2026E EBITDA (model) | C32: ='Operating Model'!$H$52 -> 2471.989 | D32: ='Operating Model'!$H$52 -> 2471.989 | E32: ='Operating Model'!$H$52 -> 2471.989 | F32: ='Operating Model'!$H$52 -> 2471.989 | H32: Equity value | L32: =L30-L31 -> 5048.6336
B33: Implied EBITDA vs 2026E | C33: =C31/C32-1 -> 0.14153615 | D33: =D31/D32-1 -> 0.1854498 | E33: =E31/E32-1 -> 0.22936344 | F33: =F31/F32-1 -> 0.23332543 | H33: Diluted shares (M) | L33: ='Operating Model'!I62 -> 466
B34: Implied net yield rebuild vs 2026E (constant unit costs) | C34: =(C31-C32)/'Operating Model'!$H$33 -> 0.04643638 | D34: =(D31-D32)/'Operating Model'!$H$33 -> 0.060843941 | E34: =(E31-E32)/'Operating Model'!$H$33 -> 0.075251502 | F34: =(F31-F32)/'Operating Model'!$H$33 -> 0.076551386 | H34: Implied value per share | L34: =L32/L33 -> 10.833978
B35: Implied net yield vs 2025A peak | C35: =('Operating Model'!$H$31/'Operating Model'!$G$31)*(1+C34)-1 -> -0.0024471849 | D35: =('Operating Model'!$H$31/'Operating Model'!$G$31)*(1+D34)-1 -> 0.011287337 | E35: =('Operating Model'!$H$31/'Operating Model'!$G$31)*(1+E34)-1 -> 0.025021858 | F35: =('Operating Model'!$H$31/'Operating Model'!$G$31)*(1+F34)-1 -> 0.026261019 | H35: Return vs current price | L35: =L34/$I$2-1 -> -0.28013437
B36: Memo: March 2026 company guide for 2026 EBITDA | C36: =Consensus!C44 -> 2950 | H36: Bull-case EV / EBITDA (re-rating) | L36: 9
H38: DCF cross-check (value at YE2026)
B39: Scenario summary (all cases live) | H39: PV of unlevered FCF, 2027E-2030E | L39: =SUM('Operating Model'!I107:L107) -> 850.73285
B40: Case | C40: Prob. | D40: FY27 net yield | E40: FY27 EBITDA | F40: EV/EBITDA | G40: Value | H40: 2030E EBITDA | L40: ='Operating Model'!L52 -> 3154.0527
B41: Bull | C41: 0.25 | D41: ='Net Yield Build'!U31 -> 0.015702552 | E41: ='Net Yield Build'!U37-'Operating Model'!$G$45*(1+'Operating Model'!$H$11)*(1+'Operating Model'!$I$11)*'Net Yield Build'!U19-'Operating Model'!$H$47*('Net Yield Build'!U19/'Net Yield Build'!T19)*0.99*'Operating Model'!$I$16/1000 -> 2787.034 | F41: =$L$36 -> 9 | G41: =(E41*F41-$F$22)/$L$33 -> 19.921257 | H41: Exit EV / EBITDA (today's market multiple) | L41: =$F$25 -> 8.4325861
B42: Base | C42: 0.5 | D42: ='Net Yield Build'!U58 -> -0.0072773132 | E42: ='Net Yield Build'!U64-'Operating Model'!$G$45*(1+'Operating Model'!$H$12)*(1+'Operating Model'!$I$12)*'Net Yield Build'!U46-'Operating Model'!$H$47*('Net Yield Build'!U46/'Net Yield Build'!T46)*0.99*'Operating Model'!$I$17/1000 -> 2472.3891 | F42: =$F$25 -> 8.4325861 | G42: =(E42*F42-$F$22)/$L$33 -> 10.833978 | H42: Terminal value | L42: =L40*L41 -> 26596.821
B43: Bear | C43: 0.25 | D43: ='Net Yield Build'!U85 -> -0.026430387 | E43: ='Net Yield Build'!U91-'Operating Model'!$G$45*(1+'Operating Model'!$H$13)*(1+'Operating Model'!$I$13)*'Net Yield Build'!U73-'Operating Model'!$H$47*('Net Yield Build'!U73/'Net Yield Build'!T73)*0.99*'Operating Model'!$I$18/1000 -> 2220.0924 | F43: =$F$25 -> 8.4325861 | G43: =(E43*F43-$F$22)/$L$33 -> 6.2684978 | H43: PV of terminal value | L43: =L42/(1+$L$24)^4 -> 18810.699
B44: Probability-weighted | C44: =SUM(C41:C43) -> 1 | G44: =C41*G41+C42*G42+C43*G43 -> 11.964428 | H44: Enterprise value | L44: =L39+L43 -> 19661.432
B45: Return vs current price | G45: =G44/$I$2-1 -> -0.20502142 | H45: (-) Net debt at YE2026E | L45: =$F$21 -> 15883.244
H46: Value per share (floored at zero) | L46: =MAX(0,(L44-L45)/L33) -> 8.1076995
H47: Return vs current price | L47: =L46/$I$2-1 -> -0.46128243
B49: Sensitivity: value per share vs FY2027E net yield growth and EV/EBITDA (selected-case costs)
...

Sheet Model vs Consensus
B2: Model vs. consensus (selected case, DCF!C9)
C4: Model | D4: Consensus | E4: Difference | F4: Difference (%)
B5: FY2026E revenue ($mm) | C5: ='Operating Model'!H38 -> 10006.098 | D5: =Consensus!C6 -> 10030 | E5: =C5-D5 -> -23.901594 | F5: =C5/D5-1 -> -0.0023830104
B6: FY2027E revenue ($mm) | C6: ='Operating Model'!I38 -> 10339.88 | D6: =Consensus!D6 -> 10570 | E6: =C6-D6 -> -230.11953 | F6: =C6/D6-1 -> -0.021771005
B7: FY2027E Adjusted EBITDA ($mm) | C7: ='Operating Model'!I52 -> 2472.3891 | D7: =Consensus!C57 -> 2693.22 | E7: =C7-D7 -> -220.83094 | F7: =C7/D7-1 -> -0.081995135
B8: FY2026E Adjusted EPS (vs. Zacks) | C8: ='Operating Model'!H63 -> 1.4404077 | D8: =Consensus!C8 -> 1.36 | E8: =C8-D8 -> 0.080407713 | F8: =C8/D8-1 -> 0.059123318
B9: FY2027E Adjusted EPS (vs. Zacks) | C9: ='Operating Model'!I63 -> 0.95137614 | D9: =Consensus!D8 -> 1.46 | E9: =C9-D9 -> -0.50862386 | F9: =C9/D9-1 -> -0.34837251
B10: FY2027E Adjusted EPS (vs. Yahoo) | C10: ='Operating Model'!I63 -> 0.95137614 | D10: =Consensus!D7 -> 1.67 | E10: =C10-D10 -> -0.71862386 | F10: =C10/D10-1 -> -0.43031369
B11: FY2027E net yield growth (vs. consensus case) | C11: ='Operating Model'!I32 -> -0.0072773132 | D11: ='Net Yield Build'!U31 -> 0.015702552 | E11: =C11-D11 -> -0.022979866 | F11: =C11-D11 -> -0.022979866
B13: Adjusted EPS by quarter: model vs. Nasdaq/Zacks consensus
B14: Quarter | C14: Model | D14: Consensus | E14: Difference
B15: 3Q26 | C15: ='Net Yield Build'!L125 -> 0.8975119 | D15: =Consensus!C12 -> 0.83 | E15: =C15-D15 -> 0.067511904
B16: 4Q26 | C16: ='Net Yield Build'!M125 -> -0.15327803 | D16: =Consensus!D12 -> -0.1 | E16: =C16-D16 -> -0.053278028
B17: 1Q27 | C17: ='Net Yield Build'!N125 -> -0.11869737 | D17: =Consensus!E12 -> -0.04 | E17: =C17-D17 -> -0.078697365
B18: 2Q27 | C18: ='Net Yield Build'!O125 -> 0.28160162 | D18: =Consensus!F12 -> 0.37 | E18: =C18-D18 -> -0.088398384
B19: 3Q27 | C19: ='Net Yield Build'!P125 -> 0.88003919 | D19: =Consensus!G12 -> 0.97 | E19: =C19-D19 -> -0.089960806
B20: 4Q27 | C20: ='Net Yield Build'!Q125 -> -0.091567307 | D20: =Consensus!H12 -> 0.16 | E20: =C20-D20 -> -0.25156731
B22: 2027 Adjusted EBITDA bridge: consensus case to model base case (Bridge Build)
B23: Step | C23: $mm
B24: Consensus case (bull inputs) | C24: ='Bridge Build'!D6 -> 2787.034
B25: 2H26 exit rate | C25: ='Bridge Build'!E7 -> -29.319419
B26: Thesis 1 -> KPI 1: fare cuts on unsold cabins (1H27) | C26: ='Bridge Build'!E8 -> -43.523693
B27: Thesis 2 -> KPI 1: late discounts on the booking shortfall (2H27) | C27: ='Bridge Build'!E9 -> -17.090892
B28: Thesis 2 -> KPI 2: occupancy | C28: ='Bridge Build'!E10 -> -76.058523
B29: Other: onboard spend growth | C29: ='Bridge Build'!E11 -> -41.546117
B30: Other: unit costs and fuel | C30: ='Bridge Build'!E12 -> -107.10628
B31: Model base case | C31: =DCF!E42 -> 2472.3891
B32: Check: steps sum to the difference | C32: =C24+SUM(C25:C30)-C31 -> 0

Sheet Bridge Build
B2: Bridge Build: 2027 EBITDA from the consensus case to our base case, one KPI at a time
B3: Each block reruns the quarterly net yield with one more group of base-case inputs switched on, in order. The change between blocks is the EBITDA attributable to that group. The last step must equal DCF!E42 (checks in row 13).
B5: Step | D5: 2027 EBITDA | E5: Change
B6: Consensus case (bull inputs) | D6: =J21 -> 2787.034
B7: 2H26 exit (3Q-4Q26 inputs) | D7: =J30 -> 2757.7146 | E7: =D7-D6 -> -29.319419
B8: Thesis 1 -> KPI 1: fare cuts on unsold cabins | D8: =J39 -> 2714.1909 | E8: =D8-D7 -> -43.523693
B9: Thesis 2 -> KPI 1: late discounts on the shortfall | D9: =J48 -> 2697.1 | E9: =D9-D8 -> -17.090892
B10: Thesis 2 -> KPI 2: occupancy | D10: =J57 -> 2621.0415 | E10: =D10-D9 -> -76.058523
B11: Other: onboard spend growth | D11: =J66 -> 2579.4953 | E11: =D11-D10 -> -41.546117
B12: Other: unit costs and fuel | D12: =J65-'Operating Model'!$G$45*(1+'Operating Model'!$H$12)*(1+'Operating Model'!$I$12)*'Net Yield Build'!$U$19-'Operating Model'!$H$47*('Net Yield Build'!$U$19/'Net Yield Build'!$T$19)*0.99*'Operating Model'!$I$17/1000 -> 2472.3891 | E12: =D12-D11 -> -107.10628
B13: Checks: block 0 = DCF!E41, final = DCF!E42 (both should be 0) | D13: =D6-DCF!E41 -> 0 | E13: =D12-DCF!E42 -> 0
B14: Block 0: Consensus case (bull inputs) | D14: 3Q26E | E14: 4Q26E | F14: 1Q27E | G14: 2Q27E | H14: 3Q27E | I14: 4Q27E | J14: FY2027E
B15: Occupancy change y/y (pts) | D15: ='Net Yield Build'!L13 -> -2.4 | E15: ='Net Yield Build'!M13 -> -2.8 | F15: ='Net Yield Build'!N13 -> -1 | G15: ='Net Yield Build'!O13 -> 0.5 | H15: ='Net Yield Build'!P13 -> 1.5 | I15: ='Net Yield Build'!Q13 -> 2
B16: Occupancy | D16: ='Net Yield Build'!H20+D15/100 -> 1.0399959 | E16: ='Net Yield Build'!I20+E15/100 -> 0.98972285 | F16: ='Net Yield Build'!J20+F15/100 -> 1.0277757 | G16: ='Net Yield Build'!K20+G15/100 -> 1.0287188 | H16: =D16+H15/100 -> 1.0549959 | I16: =E16+I15/100 -> 1.0097229
B17: Like-for-like ticket price change + mix | D17: ='Net Yield Build'!L14+'Net Yield Build'!L15+'Net Yield Build'!L17+'Net Yield Build'!L16 -> -0.0945 | E17: ='Net Yield Build'!M14+'Net Yield Build'!M15+'Net Yield Build'!M17+'Net Yield Build'!M16 -> -0.0553 | F17: ='Net Yield Build'!N14+'Net Yield Build'!N15+'Net Yield Build'!N17+'Net Yield Build'!N16 -> -0.0035598342 | G17: ='Net Yield Build'!O14+'Net Yield Build'!O15+'Net Yield Build'!O17+'Net Yield Build'!O16 -> 0.0019382335 | H17: ='Net Yield Build'!P14+'Net Yield Build'!P15+'Net Yield Build'!P17+'Net Yield Build'!P16 -> 0.01390929 | I17: ='Net Yield Build'!Q14+'Net Yield Build'!Q15+'Net Yield Build'!Q17+'Net Yield Build'!Q16 -> 0.012969926
B18: Ticket revenue per passenger day ($) | D18: ='Net Yield Build'!H25*(1+D17) -> 271.8448 | E18: ='Net Yield Build'!I25*(1+E17) -> 223.80161 | F18: ='Net Yield Build'!J25*(1+F17) -> 231.64226 | G18: ='Net Yield Build'!K25*(1+G17) -> 256.92126 | H18: =D18*(1+H17) -> 275.62597 | I18: =E18*(1+I17) -> 226.7043
B19: Onboard revenue per passenger day ($) | D19: ='Net Yield Build'!H26*(1+'Net Yield Build'!L18) -> 135.27676 | E19: ='Net Yield Build'!I26*(1+'Net Yield Build'!M18) -> 118.66645 | F19: ='Net Yield Build'!J26*(1+'Net Yield Build'!N18) -> 123.07054 | G19: ='Net Yield Build'!K26*(1+'Net Yield Build'!O18) -> 139.04939 | H19: =D19*(1+'Net Yield Build'!P18) -> 140.01145 | I19: =E19*(1+'Net Yield Build'!Q18) -> 122.81978
B20: Adjusted gross margin ($mm) | D20: ='Net Yield Build'!L19*D16*(D18*(1-'Net Yield Build'!L54)+D19*(1-'Net Yield Build'!L55)) -> 2138.9429 | E20: ='Net Yield Build'!M19*E16*(E18*(1-'Net Yield Build'!M54)+E19*(1-'Net Yield Build'!M55)) -> 1676.6932 | F20: ='Net Yield Build'!N19*F16*(F18*(1-'Net Yield Build'!N54)+F19*(1-'Net Yield Build'!N55)) -> 1821.7515 | G20: ='Net Yield Build'!O19*G16*(G18*(1-'Net Yield Build'!O54)+G19*(1-'Net Yield Build'!O55)) -> 1980.551 | H20: ='Net Yield Build'!P19*H16*(H18*(1-'Net Yield Build'!P54)+H19*(1-'Net Yield Build'!P55)) -> 2307.5726 | I20: ='Net Yield Build'!Q19*I16*(I18*(1-'Net Yield Build'!Q54)+I19*(1-'Net Yield Build'!Q55)) -> 1825.8382 | J20: =SUM(F20:I20) -> 7935.7132
B21: Adjusted EBITDA ($mm) | J21: =J20-'Operating Model'!$G$45*(1+'Operating Model'!$H$11)*(1+'Operating Model'!$I$11)*'Net Yield Build'!$U$19-'Operating Model'!$H$47*('Net Yield Build'!$U$19/'Net Yield Build'!$T$19)*0.99*'Operating Model'!$I$16/1000 -> 2787.034
B23: Block 1: 2H26 exit (3Q-4Q26 inputs) | D23: 3Q26E | E23: 4Q26E | F23: 1Q27E | G23: 2Q27E | H23: 3Q27E | I23: 4Q27E | J23: FY2027E
B24: Occupancy change y/y (pts) | D24: ='Net Yield Build'!L40 -> -2.4 | E24: ='Net Yield Build'!M40 -> -2.8 | F24: ='Net Yield Build'!N13 -> -1 | G24: ='Net Yield Build'!O13 -> 0.5 | H24: ='Net Yield Build'!P13 -> 1.5 | I24: ='Net Yield Build'!Q13 -> 2
B25: Occupancy | D25: ='Net Yield Build'!H20+D24/100 -> 1.0399959 | E25: ='Net Yield Build'!I20+E24/100 -> 0.98972285 | F25: ='Net Yield Build'!J20+F24/100 -> 1.0277757 | G25: ='Net Yield Build'!K20+G24/100 -> 1.0287188 | H25: =D25+H24/100 -> 1.0549959 | I25: =E25+I24/100 -> 1.0097229
B26: Like-for-like ticket price change + mix | D26: ='Net Yield Build'!L41+'Net Yield Build'!L42+('Net Yield Build'!L44+'KPI 2 Booking Build'!D52)+'Net Yield Build'!L16 -> -0.1005 | E26: ='Net Yield Build'!M41+'Net Yield Build'!M42+('Net Yield Build'!M44+'KPI 2 Booking Build'!E52)+'Net Yield Build'!M16 -> -0.0712 | F26: ='Net Yield Build'!N41+'Net Yield Build'!N15+'Net Yield Build'!N17+'Net Yield Build'!N16 -> -0.0035598342 | G26: ='Net Yield Build'!O41+'Net Yield Build'!O15+'Net Yield Build'!O17+'Net Yield Build'!O16 -> 0.0019382335 | H26: ='Net Yield Build'!P41+'Net Yield Build'!P15+'Net Yield Build'!P17+'Net Yield Build'!P16 -> 0.01390929 | I26: ='Net Yield Build'!Q41+'Net Yield Build'!Q15+'Net Yield Build'!Q17+'Net Yield Build'!Q16 -> 0.012969926
B27: Ticket revenue per passenger day ($) | D27: ='Net Yield Build'!H25*(1+D26) -> 270.04351 | E27: ='Net Yield Build'!I25*(1+E26) -> 220.03486 | F27: ='Net Yield Build'!J25*(1+F26) -> 231.64226 | G27: ='Net Yield Build'!K25*(1+G26) -> 256.92126 | H27: =D27*(1+H26) -> 273.79963 | I27: =E27*(1+I26) -> 222.8887
B28: Onboard revenue per passenger day ($) | D28: ='Net Yield Build'!H26*(1+'Net Yield Build'!L45) -> 135.27676 | E28: ='Net Yield Build'!I26*(1+'Net Yield Build'!M45) -> 118.66645 | F28: ='Net Yield Build'!J26*(1+'Net Yield Build'!N18) -> 123.07054 | G28: ='Net Yield Build'!K26*(1+'Net Yield Build'!O18) -> 139.04939 | H28: =D28*(1+'Net Yield Build'!P18) -> 140.01145 | I28: =E28*(1+'Net Yield Build'!Q18) -> 122.81978
B29: Adjusted gross margin ($mm) | D29: ='Net Yield Build'!L19*D25*(D27*(1-'Net Yield Build'!L54)+D28*(1-'Net Yield Build'!L55)) -> 2129.5244 | E29: ='Net Yield Build'!M19*E25*(E27*(1-'Net Yield Build'!M54)+E28*(1-'Net Yield Build'!M55)) -> 1658.8169 | F29: ='Net Yield Build'!N19*F25*(F27*(1-'Net Yield Build'!N54)+F28*(1-'Net Yield Build'!N55)) -> 1821.7515 | G29: ='Net Yield Build'!O19*G25*(G27*(1-'Net Yield Build'!O54)+G28*(1-'Net Yield Build'!O55)) -> 1980.551 | H29: ='Net Yield Build'!P19*H25*(H27*(1-'Net Yield Build'!P54)+H28*(1-'Net Yield Build'!P55)) -> 2297.5171 | I29: ='Net Yield Build'!Q19*I25*(I27*(1-'Net Yield Build'!Q54)+I28*(1-'Net Yield Build'!Q55)) -> 1806.5743 | J29: =SUM(F29:I29) -> 7906.3938
B30: Adjusted EBITDA ($mm) | J30: =J29-'Operating Model'!$G$45*(1+'Operating Model'!$H$11)*(1+'Operating Model'!$I$11)*'Net Yield Build'!$U$19-'Operating Model'!$H$47*('Net Yield Build'!$U$19/'Net Yield Build'!$T$19)*0.99*'Operating Model'!$I$16/1000 -> 2757.7146
B32: Block 2: Thesis 1 -> KPI 1: fare cuts on unsold cabins | D32: 3Q26E | E32: 4Q26E | F32: 1Q27E | G32: 2Q27E | H32: 3Q27E | I32: 4Q27E | J32: FY2027E
B33: Occupancy change y/y (pts) | D33: ='Net Yield Build'!L40 -> -2.4 | E33: ='Net Yield Build'!M40 -> -2.8 | F33: ='Net Yield Build'!N13 -> -1 | G33: ='Net Yield Build'!O13 -> 0.5 | H33: ='Net Yield Build'!P13 -> 1.5 | I33: ='Net Yield Build'!Q13 -> 2
B34: Occupancy | D34: ='Net Yield Build'!H20+D33/100 -> 1.0399959 | E34: ='Net Yield Build'!I20+E33/100 -> 0.98972285 | F34: ='Net Yield Build'!J20+F33/100 -> 1.0277757 | G34: ='Net Yield Build'!K20+G33/100 -> 1.0287188 | H34: =D34+H33/100 -> 1.0549959 | I34: =E34+I33/100 -> 1.0097229
B35: Like-for-like ticket price change + mix | D35: ='Net Yield Build'!L41+'Net Yield Build'!L42+('Net Yield Build'!L44+'KPI 2 Booking Build'!D52)+'Net Yield Build'!L16 -> -0.1005 | E35: ='Net Yield Build'!M41+'Net Yield Build'!M42+('Net Yield Build'!M44+'KPI 2 Booking Build'!E52)+'Net Yield Build'!M16 -> -0.0712 | F35: ='Net Yield Build'!N41+'Net Yield Build'!N42+'Net Yield Build'!N17+'Net Yield Build'!N16 -> -0.018407702 | G35: ='Net Yield Build'!O41+'Net Yield Build'!O42+'Net Yield Build'!O17+'Net Yield Build'!O16 -> -0.013735886 | H35: ='Net Yield Build'!P41+'Net Yield Build'!P42+'Net Yield Build'!P17+'Net Yield Build'!P16 -> 0.012164155 | I35: ='Net Yield Build'!Q41+'Net Yield Build'!Q42+'Net Yield Build'!Q17+'Net Yield Build'!Q16 -> 0.0089097768
B36: Ticket revenue per passenger day ($) | D36: ='Net Yield Build'!H25*(1+D35) -> 270.04351 | E36: ='Net Yield Build'!I25*(1+E35) -> 220.03486 | F36: ='Net Yield Build'!J25*(1+F35) -> 228.19058 | G36: ='Net Yield Build'!K25*(1+G35) -> 252.90204 | H36: =D36*(1+H35) -> 273.32836 | I36: =E36*(1+I35) -> 221.99532
B37: Onboard revenue per passenger day ($) | D37: ='Net Yield Build'!H26*(1+'Net Yield Build'!L45) -> 135.27676 | E37: ='Net Yield Build'!I26*(1+'Net Yield Build'!M45) -> 118.66645 | F37: ='Net Yield Build'!J26*(1+'Net Yield Build'!N18) -> 123.07054 | G37: ='Net Yield Build'!K26*(1+'Net Yield Build'!O18) -> 139.04939 | H37: =D37*(1+'Net Yield Build'!P18) -> 140.01145 | I37: =E37*(1+'Net Yield Build'!Q18) -> 122.81978
B38: Adjusted gross margin ($mm) | D38: ='Net Yield Build'!L19*D34*(D36*(1-'Net Yield Build'!L54)+D37*(1-'Net Yield Build'!L55)) -> 2129.5244 | E38: ='Net Yield Build'!M19*E34*(E36*(1-'Net Yield Build'!M54)+E37*(1-'Net Yield Build'!M55)) -> 1658.8169 | F38: ='Net Yield Build'!N19*F34*(F36*(1-'Net Yield Build'!N54)+F37*(1-'Net Yield Build'!N55)) -> 1804.6608 | G38: ='Net Yield Build'!O19*G34*(G36*(1-'Net Yield Build'!O54)+G37*(1-'Net Yield Build'!O55)) -> 1961.2231 | H38: ='Net Yield Build'!P19*H34*(H36*(1-'Net Yield Build'!P54)+H37*(1-'Net Yield Build'!P55)) -> 2294.9224 | I38: ='Net Yield Build'!Q19*I34*(I36*(1-'Net Yield Build'!Q54)+I37*(1-'Net Yield Build'!Q55)) -> 1802.0639 | J38: =SUM(F38:I38) -> 7862.8701
B39: Adjusted EBITDA ($mm) | J39: =J38-'Operating Model'!$G$45*(1+'Operating Model'!$H$11)*(1+'Operating Model'!$I$11)*'Net Yield Build'!$U$19-'Operating Model'!$H$47*('Net Yield Build'!$U$19/'Net Yield Build'!$T$19)*0.99*'Operating Model'!$I$16/1000 -> 2714.1909
B41: Block 3: Thesis 2 -> KPI 1: late discounts on the shortfall | D41: 3Q26E | E41: 4Q26E | F41: 1Q27E | G41: 2Q27E | H41: 3Q27E | I41: 4Q27E | J41: FY2027E
B42: Occupancy change y/y (pts) | D42: ='Net Yield Build'!L40 -> -2.4 | E42: ='Net Yield Build'!M40 -> -2.8 | F42: ='Net Yield Build'!N13 -> -1 | G42: ='Net Yield Build'!O13 -> 0.5 | H42: ='Net Yield Build'!P13 -> 1.5 | I42: ='Net Yield Build'!Q13 -> 2
B43: Occupancy | D43: ='Net Yield Build'!H20+D42/100 -> 1.0399959 | E43: ='Net Yield Build'!I20+E42/100 -> 0.98972285 | F43: ='Net Yield Build'!J20+F42/100 -> 1.0277757 | G43: ='Net Yield Build'!K20+G42/100 -> 1.0287188 | H43: =D43+H42/100 -> 1.0549959 | I43: =E43+I42/100 -> 1.0097229
B44: Like-for-like ticket price change + mix | D44: ='Net Yield Build'!L41+'Net Yield Build'!L42+('Net Yield Build'!L44+'KPI 2 Booking Build'!D52)+'Net Yield Build'!L16 -> -0.1005 | E44: ='Net Yield Build'!M41+'Net Yield Build'!M42+('Net Yield Build'!M44+'KPI 2 Booking Build'!E52)+'Net Yield Build'!M16 -> -0.0712 | F44: ='Net Yield Build'!N41+'Net Yield Build'!N42+('Net Yield Build'!N44+'KPI 2 Booking Build'!F52)+'Net Yield Build'!N16 -> -0.018407702 | G44: ='Net Yield Build'!O41+'Net Yield Build'!O42+('Net Yield Build'!O44+'KPI 2 Booking Build'!G52)+'Net Yield Build'!O16 -> -0.013735886 | H44: ='Net Yield Build'!P41+'Net Yield Build'!P42+('Net Yield Build'!P44+'KPI 2 Booking Build'!H52)+'Net Yield Build'!P16 -> 0.0055849259 | I44: ='Net Yield Build'!Q41+'Net Yield Build'!Q42+('Net Yield Build'!Q44+'KPI 2 Booking Build'!I52)+'Net Yield Build'!Q16 -> 0.0023305479
B45: Ticket revenue per passenger day ($) | D45: ='Net Yield Build'!H25*(1+D44) -> 270.04351 | E45: ='Net Yield Build'!I25*(1+E44) -> 220.03486 | F45: ='Net Yield Build'!J25*(1+F44) -> 228.19058 | G45: ='Net Yield Build'!K25*(1+G44) -> 252.90204 | H45: =D45*(1+H44) -> 271.55169 | I45: =E45*(1+I44) -> 220.54767
...

Sheet Operating Model
B2: NCLH Operating Model | F2: FY2024A | G2: FY2025A | H2: FY2026E | I2: FY2027E | J2: FY2028E | K2: FY2029E | L2: FY2030E
B3: $mm except per-share and per-day data | F3: 2024-12-31 | G3: 2025-12-31 | H3: 2026-12-31 | I3: 2027-12-31 | J3: 2028-12-31 | K3: 2029-12-31 | L3: 2030-12-31
B5: Case inputs (selected by DCF!C9)
B6: Net yield growth 2028E-30E: Bull | J6: 0.035 | K6: 0.03 | L6: 0.03
B7: Net yield growth 2028E-30E: Base | J7: 0.025 | K7: 0.025 | L7: 0.025
B8: Net yield growth 2028E-30E: Bear | J8: 0.01 | K8: 0.015 | L8: 0.015
B9: Net yield growth 2028E-30E: selected | J9: =CHOOSE(DCF!$C$9,J6,J7,J8) -> 0.025 | K9: =CHOOSE(DCF!$C$9,K6,K7,K8) -> 0.025 | L9: =CHOOSE(DCF!$C$9,L6,L7,L8) -> 0.025
B11: NCC ex fuel per capacity day growth: Bull | H11: 0 | I11: -0.005 | J11: 0.015 | K11: 0.015 | L11: 0.015
B12: NCC ex fuel per capacity day growth: Base | H12: 0 | I12: 0.01 | J12: 0.02 | K12: 0.02 | L12: 0.02
B13: NCC ex fuel per capacity day growth: Bear | H13: 0 | I13: 0.015 | J13: 0.025 | K13: 0.025 | L13: 0.025
B14: NCC ex fuel per capacity day growth: selected | H14: =CHOOSE(DCF!$C$9,H11,H12,H13) -> 0 | I14: =CHOOSE(DCF!$C$9,I11,I12,I13) -> 0.01 | J14: =CHOOSE(DCF!$C$9,J11,J12,J13) -> 0.02 | K14: =CHOOSE(DCF!$C$9,K11,K12,K13) -> 0.02 | L14: =CHOOSE(DCF!$C$9,L11,L12,L13) -> 0.02
B16: Fuel price per metric ton, net of hedges ($): Bull | H16: 790 | I16: 760 | J16: 760 | K16: 760 | L16: 760
B17: Fuel price per metric ton, net of hedges ($): Base | H17: 810 | I17: 800 | J17: 800 | K17: 800 | L17: 800
B18: Fuel price per metric ton, net of hedges ($): Bear | H18: 830 | I18: 850 | J18: 850 | K18: 850 | L18: 850
B19: Fuel price per metric ton, net of hedges ($): selected | H19: =CHOOSE(DCF!$C$9,H16,H17,H18) -> 810 | I19: =CHOOSE(DCF!$C$9,I16,I17,I18) -> 800 | J19: =CHOOSE(DCF!$C$9,J16,J17,J18) -> 800 | K19: =CHOOSE(DCF!$C$9,K16,K17,K18) -> 800 | L19: =CHOOSE(DCF!$C$9,L16,L17,L18) -> 800
B21: Advance ticket sales at YE2026 ($mm): Bull | H21: 3200
B22: Advance ticket sales at YE2026 ($mm): Base | H22: 3000
B23: Advance ticket sales at YE2026 ($mm): Bear | H23: 2900
B24: Advance ticket sales at YE2026 ($mm): selected | H24: =CHOOSE(DCF!$C$9,H21,H22,H23) -> 3000
B26: Capacity, occupancy and net yield
B27: Capacity days (M) | F27: ='Quarterly (A)'!L29 -> 23.4454 | G27: ='Quarterly (A)'!M29 -> 24.4336 | H27: ='Net Yield Build'!T94 -> 26.249873 | I27: ='Net Yield Build'!U94 -> 27.121933 | J27: =I27*(1+J28) -> 27.963719 | K27: =J27*(1+K28) -> 29.049173 | L27: =K27*(1+L28) -> 30.334185
B28: Capacity growth | G28: =G27/F27-1 -> 0.042148993 | H28: =H27/G27-1 -> 0.074335075 | I28: =I27/H27-1 -> 0.033221479 | J28: ='Fleet Build'!L60 -> 0.031037101 | K28: ='Fleet Build'!M60 -> 0.038816504 | L28: ='Fleet Build'!N60 -> 0.04423575
B29: Occupancy | F29: ='Quarterly (A)'!L31 -> 1.0489606 | G29: ='Quarterly (A)'!M31 -> 1.0345753 | H29: ='Net Yield Build'!T95 -> 1.0229831 | I29: ='Net Yield Build'!U95 -> 1.0206424 | J29: =I29 -> 1.0206424 | K29: =J29 -> 1.0206424 | L29: =K29 -> 1.0206424
B30: Passenger cruise days (M) | F30: =F27*F29 -> 24.5933 | G30: =G27*G29 -> 25.2784 | H30: =H27*H29 -> 26.853176 | I30: =I27*I29 -> 27.681795 | J30: =J27*J29 -> 28.540957 | K30: =K27*K29 -> 29.648818 | L30: =L27*L29 -> 30.960355
B31: Net yield ($ per capacity day) | F31: ='Quarterly (A)'!L32 -> 294.32874 | G31: ='Quarterly (A)'!M32 -> 301.0962 | H31: ='Net Yield Build'!T102 -> 287.03069 | I31: ='Net Yield Build'!U102 -> 284.94188 | J31: =I31*(1+J9) -> 292.06543 | K31: =J31*(1+K9) -> 299.36706 | L31: =K31*(1+L9) -> 306.85124
B32: Net yield growth | G32: =G31/F31-1 -> 0.022992852 | H32: =H31/G31-1 -> -0.046714321 | I32: =I31/H31-1 -> -0.0072773132 | J32: =J31/I31-1 -> 0.025 | K32: =K31/J31-1 -> 0.025 | L32: =L31/K31-1 -> 0.025
B33: Adjusted gross margin ($mm) | F33: =F31*F27 -> 6900.655 | G33: =G31*G27 -> 7356.864 | H33: =H31*H27 -> 7534.5193 | I33: =I31*I27 -> 7728.1746 | J33: =J31*J27 -> 8167.2356 | K33: =K31*K27 -> 8696.3656 | L33: =L31*L27 -> 9308.0822
B35: Revenue
B36: Passenger ticket revenue | F36: ='Quarterly (A)'!L5 -> 6415.545 | G36: ='Quarterly (A)'!M5 -> 6687.667 | H36: ='Net Yield Build'!T104 -> 6590.2719 | I36: ='Net Yield Build'!U104 -> 6753.9799 | J36: =I36*J33/I33 -> 7137.6939 | K36: =J36*K33/J33 -> 7600.1231 | L36: =K36*L33/K33 -> 8134.7283
B37: Onboard and other revenue | F37: ='Quarterly (A)'!L6 -> 3064.106 | G37: ='Quarterly (A)'!M6 -> 3139.925 | H37: ='Net Yield Build'!T105 -> 3415.8265 | I37: ='Net Yield Build'!U105 -> 3585.9006 | J37: =I37*J33/I33 -> 3789.6265 | K37: =J37*K33/J33 -> 4035.1447 | L37: =K37*L33/K33 -> 4318.9834
B38: Total revenue | F38: =F36+F37 -> 9479.651 | G38: =G36+G37 -> 9827.592 | H38: =H36+H37 -> 10006.098 | I38: =I36+I37 -> 10339.88 | J38: =J36+J37 -> 10927.32 | K38: =K36+K37 -> 11635.268 | L38: =L36+L37 -> 12453.712
B39: Revenue growth | G39: =G38/F38-1 -> 0.036703988 | H39: =H38/G38-1 -> 0.018163799 | I39: =I38/H38-1 -> 0.033357864 | J39: =J38/I38-1 -> 0.056813029 | K39: =K38/J38-1 -> 0.064786916 | L39: =L38/K38-1 -> 0.070341644
B40: Commissions, transportation and other | F40: ='Quarterly (A)'!L8 -> 1917.443 | G40: ='Quarterly (A)'!M8 -> 1782.004 | H40: ='Net Yield Build'!T107 -> 1744.157 | I40: ='Net Yield Build'!U107 -> 1847.3597 | J40: =I40*J33/I33 -> 1952.3138 | K40: =J40*K33/J33 -> 2078.7981 | L40: =K40*L33/K33 -> 2225.0242
B41: Onboard and other expense | F41: ='Quarterly (A)'!L9 -> 661.553 | G41: ='Quarterly (A)'!M9 -> 688.724 | H41: ='Net Yield Build'!T108 -> 727.42208 | I41: ='Net Yield Build'!U108 -> 764.34623 | J41: =I41*J33/I33 -> 807.77106 | K41: =J41*K33/J33 -> 860.10405 | L41: =K41*L33/K33 -> 920.60518
B42: Gross margin check (revenue - commissions - onboard costs) | F42: =F38-F40-F41-F33 -> 0 | G42: =G38-G40-G41-G33 -> 0 | H42: =H38-H40-H41-H33 -> 0 | I42: =I38-I40-I41-I33 -> 0 | J42: =J38-J40-J41-J33 -> 0 | K42: =K38-K40-K41-K33 -> 0 | L42: =L38-L40-L41-L33 -> 0
B44: Costs
B45: Adjusted NCC ex fuel per capacity day ($) | F45: ='Quarterly (A)'!L21/'Quarterly (A)'!L29 -> 160.0229 | G45: ='Quarterly (A)'!M21/'Quarterly (A)'!M29 -> 161.69336 | H45: =G45*(1+H14) -> 161.69336 | I45: =H45*(1+I14) -> 163.3103 | J45: =I45*(1+J14) -> 166.5765 | K45: =J45*(1+K14) -> 169.90803 | L45: =K45*(1+L14) -> 173.3062
B46: Adjusted NCC ex fuel ($mm) | F46: =F45*F27 -> 3751.801 | G46: =G45*G27 -> 3950.751 | H46: =H45*H27 -> 4244.4304 | I46: =I45*I27 -> 4429.291 | J46: =J45*J27 -> 4658.0986 | K46: =K45*K27 -> 4935.6879 | L46: =L45*L27 -> 5257.1022
B47: Fuel consumption (k metric tons) | H47: =Consensus!C39 -> 1010 | I47: =H47*(1+I28)*(1-0.01) -> 1033.1182 | J47: =I47*(1+J28)*(1-0.01) -> 1054.5313 | K47: =J47*(1+K28)*(1-0.01) -> 1084.5099 | L47: =K47*(1+L28)*(1-0.01) -> 1121.1592
B48: Fuel price per ton, net of hedges ($) | H48: =H19 -> 810 | I48: =I19 -> 800 | J48: =J19 -> 800 | K48: =K19 -> 800 | L48: =L19 -> 800
...

Sheet Net Yield Build
B2: Net Yield Build: occupancy x (ticket + onboard - commissions - onboard costs) per passenger day | F2: Q1'25A | G2: Q2'25A | H2: Q3'25A | I2: Q4'25A | J2: Q1'26A | K2: Q2'26A | L2: Q3'26E | M2: Q4'26E | N2: Q1'27E | O2: Q2'27E | P2: Q3'27E | Q2: Q4'27E | S2: FY2025A | T2: FY2026E | U2: FY2027E
B3: $ per day unless noted. Case switch: DCF!C9 (1 = Bull, consensus-calibrated; 2 = Base; 3 = Bear)
B5: Common drivers (all cases)
B6: Capacity days growth y/y (3Q-4Q26 guidance; 2027 Fleet Qtr Build) | C6: fleet / guidance | L6: 0.05957 | M6: 0.0326 | N6: ='Fleet Qtr Build'!L12 -> 0.033419921 | O6: ='Fleet Qtr Build'!M12 -> 0.00079604886 | P6: ='Fleet Qtr Build'!N12 -> 0.04866049 | Q6: ='Fleet Qtr Build'!O12 -> 0.04983149
B7: Caribbean share of NCLH capacity (KPI 1 build) | C7: deployment est. | L7: ='KPI 1 Price Build'!D10 -> 0.18 | M7: ='KPI 1 Price Build'!E10 -> 0.5 | N7: ='KPI 1 Price Build'!F10 -> 0.62 | O7: ='KPI 1 Price Build'!G10 -> 0.38 | P7: ='KPI 1 Price Build'!H10 -> 0.2 | Q7: ='KPI 1 Price Build'!I10 -> 0.48
B8: Observed NCL fare change: Caribbean (KPI 1 build) | L8: ='KPI 1 Price Build'!D16 -> 0 | M8: ='KPI 1 Price Build'!E16 -> -0.36 | N8: ='KPI 1 Price Build'!F16 -> -0.145 | O8: ='KPI 1 Price Build'!G16 -> -0.145 | P8: ='KPI 1 Price Build'!H16 -> -0.02 | Q8: ='KPI 1 Price Build'!I16 -> -0.02
B9: Observed NCL fare change: other regions (KPI 1 build) | L9: ='KPI 1 Price Build'!D17 -> 0 | M9: ='KPI 1 Price Build'!E17 -> -0.13434783 | N9: ='KPI 1 Price Build'!F17 -> -0.028461538 | O9: ='KPI 1 Price Build'!G17 -> -0.028461538 | P9: ='KPI 1 Price Build'!H17 -> -0.003 | Q9: ='KPI 1 Price Build'!I17 -> -0.003
B10: Full-fare commission step-up (pts of ticket; KPI 1 build) | C10: NCF elimination | L10: ='KPI 1 Price Build'!D49 -> 0.006 | M10: ='KPI 1 Price Build'!E49 -> 0.009 | N10: ='KPI 1 Price Build'!F49 -> 0.0130005 | O10: ='KPI 1 Price Build'!G49 -> 0.0109995 | P10: ='KPI 1 Price Build'!H49 -> 0.0075 | Q10: ='KPI 1 Price Build'!I49 -> 0.0049995
B12: Bull case: Street-like recovery (approximates consensus)
B13: Occupancy change y/y (pts) | L13: -2.4 | M13: -2.8 | N13: -1 | O13: 0.5 | P13: 1.5 | Q13: 2
B14: Underlying price change y/y (3Q-4Q26 calibrated to guidance) | L14: -0.0995 | M14: -0.027403856 | N14: 0.005 | O14: 0.005 | P14: 0.005 | Q14: 0.005
B15: Thesis 1: fare cuts on unsold cabins (KPI 1 build) | L15: ='KPI 1 Price Build'!D40 -> 0 | M15: ='KPI 1 Price Build'!E40 -> -0.032896144 | N15: ='KPI 1 Price Build'!F40 -> -0.018559834 | O15: ='KPI 1 Price Build'!G40 -> -0.013061766 | P15: ='KPI 1 Price Build'!H40 -> -0.0010907097 | Q15: ='KPI 1 Price Build'!I40 -> -0.0020300744
B16: Brand / new-ship mix effect on ticket price | L16: 0.005 | M16: 0.005 | N16: 0.01 | O16: 0.01 | P16: 0.01 | Q16: 0.01
B17: Thesis 2: late discounts on the booking shortfall (KPI 2 build) | L17: 0 | M17: 0 | N17: 0 | O17: 0 | P17: 0 | Q17: 0
B18: Onboard revenue per passenger day growth | L18: 0.04 | M18: 0.03 | N18: 0.035 | O18: 0.03 | P18: 0.035 | Q18: 0.035
B19: Capacity days (M) | F19: ='Quarterly (A)'!E29 -> 5.7006 | G19: ='Quarterly (A)'!F29 -> 6.0523 | H19: ='Quarterly (A)'!G29 -> 6.4176 | I19: ='Quarterly (A)'!H29 -> 6.2631 | J19: ='Quarterly (A)'!I29 -> 6.393 | K19: ='Quarterly (A)'!J29 -> 6.5897 | L19: =H19*(1+L$6) -> 6.7998964 | M19: =I19*(1+M$6) -> 6.4672771 | N19: =J19*(1+N$6) -> 6.6066536 | O19: =K19*(1+O$6) -> 6.5949457 | P19: =L19*(1+P$6) -> 7.1307827 | Q19: =M19*(1+Q$6) -> 6.7895511 | S19: =SUM(F19:I19) -> 24.4336 | T19: =SUM(J19:M19) -> 26.249873 | U19: =SUM(N19:Q19) -> 27.121933
B20: Occupancy | F20: ='Quarterly (A)'!E31 -> 1.0151914 | G20: ='Quarterly (A)'!F31 -> 1.0390761 | H20: ='Quarterly (A)'!G31 -> 1.0639959 | I20: ='Quarterly (A)'!H31 -> 1.0177229 | J20: ='Quarterly (A)'!I31 -> 1.0377757 | K20: ='Quarterly (A)'!J31 -> 1.0237188 | L20: =H20+L13/100 -> 1.0399959 | M20: =I20+M13/100 -> 0.98972285 | N20: =J20+N13/100 -> 1.0277757 | O20: =K20+O13/100 -> 1.0287188 | P20: =L20+P13/100 -> 1.0549959 | Q20: =M20+Q13/100 -> 1.0097229 | S20: =S21/S19 -> 1.0345753 | T20: =T21/T19 -> 1.0229831 | U20: =U21/U19 -> 1.0306424
B21: Passenger cruise days (M) | F21: =F19*F20 -> 5.7872 | G21: =G19*G20 -> 6.2888 | H21: =H19*H20 -> 6.8283 | I21: =I19*I20 -> 6.3741 | J21: =J19*J20 -> 6.6345 | K21: =K19*K20 -> 6.746 | L21: =L19*L20 -> 7.0718643 | M21: =M19*M20 -> 6.4008119 | ... Q21: =Q19*Q20 -> 6.8555649 | S21: =SUM(F21:I21) -> 25.2784 | T21: =SUM(J21:M21) -> 26.853176 | U21: =SUM(N21:Q21) -> 27.953014
B22: Underlying price change | L22: =L14 -> -0.0995 | M22: =M14 -> -0.027403856 | N22: =N14 -> 0.005 | O22: =O14 -> 0.005 | P22: =P14 -> 0.005 | Q22: =Q14 -> 0.005
B23: Thesis effects (Thesis 1 + Thesis 2) | L23: =L15+L17 -> 0 | M23: =M15+M17 -> -0.032896144 | N23: =N15+N17 -> -0.018559834 | O23: =O15+O17 -> -0.013061766 | P23: =P15+P17 -> -0.0010907097 | Q23: =Q15+Q17 -> -0.0020300744
B24: KPI 1: like-for-like ticket price change y/y | L24: =L22+L23 -> -0.0995 | M24: =M22+M23 -> -0.0603 | N24: =N22+N23 -> -0.013559834 | O24: =O22+O23 -> -0.0080617665 | P24: =P22+P23 -> 0.0039092903 | Q24: =Q22+Q23 -> 0.0029699256
B25: Ticket revenue per passenger day | F25: ='Quarterly (A)'!E34 -> 245.14169 | G25: ='Quarterly (A)'!F34 -> 271.75057 | H25: ='Quarterly (A)'!G34 -> 300.21513 | I25: ='Quarterly (A)'!H34 -> 236.90231 | J25: ='Quarterly (A)'!I34 -> 232.46982 | K25: ='Quarterly (A)'!J34 -> 256.42425 | L25: =H25*(1+L24+L16) -> 271.8448 | M25: =I25*(1+M24+M16) -> 223.80161 | N25: =J25*(1+N24+N16) -> 231.64226 | O25: =K25*(1+O24+O16) -> 256.92126 | P25: =L25*(1+P24+P16) -> 275.62597 | Q25: =M25*(1+Q24+Q16) -> 226.7043 | S25: =S32/S21 -> 264.56053 | T25: =T32/T21 -> 246.79094 | U25: =U32/U21 -> 248.40382
B26: Onboard revenue per passenger day | F26: ='Quarterly (A)'!E35 -> 122.48911 | G26: ='Quarterly (A)'!F35 -> 128.5638 | H26: ='Quarterly (A)'!G35 -> 130.07381 | I26: ='Quarterly (A)'!H35 -> 115.21015 | J26: ='Quarterly (A)'!I35 -> 118.90873 | K26: ='Quarterly (A)'!J35 -> 134.99941 | L26: =H26*(1+L18) -> 135.27676 | M26: =I26*(1+M18) -> 118.66645 | N26: =J26*(1+N18) -> 123.07054 | O26: =K26*(1+O18) -> 139.04939 | P26: =L26*(1+P18) -> 140.01145 | Q26: =M26*(1+Q18) -> 122.81978 | S26: =S33/S21 -> 124.21376 | T26: =T33/T21 -> 127.20382 | U26: =U33/U21 -> 131.44647
B27: Commissions/transport % of ticket | F27: ='Quarterly (A)'!E36 -> 0.27866882 | G27: ='Quarterly (A)'!F36 -> 0.28545306 | H27: ='Quarterly (A)'!G36 -> 0.25462997 | I27: ='Quarterly (A)'!H36 -> 0.24955978 | J27: ='Quarterly (A)'!I36 -> 0.25779653 | K27: ='Quarterly (A)'!J36 -> 0.28018115 | L27: =H27+L$10 -> 0.26062997 | M27: =I27+M$10 -> 0.25855978 | N27: =J27+N$10 -> 0.27079703 | O27: =K27+O$10 -> 0.29118065 | P27: =L27+P$10 -> 0.26812997 | Q27: =M27+Q$10 -> 0.26355928 | S27: =S35/S32 -> 0.26646123 | T27: =T35/T32 -> 0.26462639 | U27: =U35/U32 -> 0.27349742
B28: Onboard costs % of onboard revenue | F28: ='Quarterly (A)'!E37 -> 0.19588669 | G28: ='Quarterly (A)'!F37 -> 0.23213508 | H28: ='Quarterly (A)'!G37 -> 0.24995074 | I28: ='Quarterly (A)'!H37 -> 0.19088704 | J28: ='Quarterly (A)'!I37 -> 0.19250602 | K28: ='Quarterly (A)'!J37 -> 0.21021713 | L28: =H28 -> 0.24995074 | M28: =I28 -> 0.19088704 | N28: =J28 -> 0.19250602 | O28: =K28 -> 0.21021713 | P28: =L28 -> 0.24995074 | Q28: =M28 -> 0.19088704 | S28: =S36/S33 -> 0.21934409 | T28: =T36/T33 -> 0.21295639 | U28: =U36/U33 -> 0.2131496
B29: Net per diem | F29: =F25+F26-F25*F27-F26*F28 -> 275.32347 | G29: =G25+G26-G25*G27-G26*G28 -> 292.89817 | H29: =H25+H26-H25*H27-H26*H28 -> 321.33313 | I29: =I25+I26-I25*I27-I26*I28 -> 270.99904 | J29: =J25+J26-J25*J27-J26*J28 -> 268.55799 | K29: =K25+K26-K25*K27-K26*K28 -> 291.19923 | L29: =L25+L26-L25*L27-L26*L28 -> 302.45814 | M29: =M25+M26-M25*M27-M26*M28 -> 261.95008 | ... Q29: =Q25+Q26-Q25*Q27-Q26*Q28 -> 266.32935 | S29: =S37/S21 -> 291.03361 | T29: =T37/T21 -> 281.5985 | U29: =U37/U21 -> 283.89472
B30: NET YIELD ($ per capacity day) | F30: =F29*F20 -> 279.50602 | G30: =G29*G20 -> 304.34347 | H30: =H29*H20 -> 341.89713 | I30: =I29*I20 -> 275.80192 | J30: =J29*J20 -> 278.70296 | K30: =K29*K20 -> 298.10614 | L30: =L29*L20 -> 314.55522 | M30: =M29*M20 -> 259.25798 | ... Q30: =Q29*Q20 -> 268.91883 | S30: =S37/S19 -> 301.0962 | T30: =T37/T19 -> 288.0705 | U30: =U37/U19 -> 292.59394
B31: Net yield y/y | J31: =J30/F30-1 -> -0.0028731423 | K31: =K30/G30-1 -> -0.020494402 | L31: =L30/H30-1 -> -0.079971158 | M31: =M30/I30-1 -> -0.059984861 | N31: =N30/J30-1 -> -0.010613405 | O31: =O30/K30-1 -> 0.007404509 | P31: =P30/L30-1 -> 0.028777065 | Q31: =Q30/M30-1 -> 0.037263476 | S31: =S30/'Quarterly (A)'!L32-1 -> 0.022992852 | T31: =T30/S30-1 -> -0.043260922 | U31: =U30/T30-1 -> 0.015702552
B32: Passenger ticket revenue ($mm) | F32: =F25*F21 -> 1418.684 | G32: =G25*G21 -> 1708.985 | H32: =H25*H21 -> 2049.959 | I32: =I25*I21 -> 1510.039 | J32: =J25*J21 -> 1542.321 | K32: =K25*K21 -> 1729.838 | L32: =L25*L21 -> 1922.4496 | M32: =M25*M21 -> 1432.512 | ... Q32: =Q25*Q21 -> 1554.186 | S32: =SUM(F32:I32) -> 6687.667 | T32: =SUM(J32:M32) -> 6627.1206 | U32: =SUM(N32:Q32) -> 6943.6355
B33: Onboard and other revenue ($mm) | F33: =F26*F21 -> 708.869 | G33: =G26*G21 -> 808.512 | H33: =H26*H21 -> 888.183 | I33: =I26*I21 -> 734.361 | J33: =J26*J21 -> 788.9 | K33: =K26*K21 -> 910.706 | L33: =L26*L21 -> 956.65891 | M33: =M26*M21 -> 759.56164 | ... Q33: =Q26*Q21 -> 841.99896 | S33: =SUM(F33:I33) -> 3139.925 | T33: =SUM(J33:M33) -> 3415.8265 | U33: =SUM(N33:Q33) -> 3674.325
B34: Total revenue ($mm) | F34: =F32+F33 -> 2127.553 | G34: =G32+G33 -> 2517.497 | H34: =H32+H33 -> 2938.142 | I34: =I32+I33 -> 2244.4 | J34: =J32+J33 -> 2331.221 | K34: =K32+K33 -> 2640.544 | L34: =L32+L33 -> 2879.1085 | M34: =M32+M33 -> 2192.0736 | ... Q34: =Q32+Q33 -> 2396.185 | S34: =SUM(F34:I34) -> 9827.592 | T34: =SUM(J34:M34) -> 10042.947 | U34: =SUM(N34:Q34) -> 10617.96
B35: Commissions, transportation and other ($mm) | F35: =F32*F27 -> 395.343 | G35: =G32*G27 -> 487.835 | H35: =H32*H27 -> 521.981 | I35: =I32*I27 -> 376.845 | J35: =J32*J27 -> 397.605 | K35: =K32*K27 -> 484.668 | L35: =L32*L27 -> 501.04797 | M35: =M32*M27 -> 370.38999 | ... Q35: =Q32*Q27 -> 409.62016 | S35: =SUM(F35:I35) -> 1782.004 | T35: =SUM(J35:M35) -> 1753.711 | U35: =SUM(N35:Q35) -> 1899.0664
B36: Onboard and other expense ($mm) | F36: =F33*F28 -> 138.858 | G36: =G33*G28 -> 187.684 | H36: =H33*H28 -> 222.002 | I36: =I33*I28 -> 140.18 | J36: =J33*J28 -> 151.868 | K36: =K33*K28 -> 191.446 | L36: =L33*L28 -> 239.11761 | M36: =M33*M28 -> 144.99048 | ... Q36: =Q33*Q28 -> 160.72669 | S36: =SUM(F36:I36) -> 688.724 | T36: =SUM(J36:M36) -> 727.42208 | U36: =SUM(N36:Q36) -> 783.18089
B37: Adjusted gross margin ($mm) | F37: =F34-F35-F36 -> 1593.352 | G37: =G34-G35-G36 -> 1841.978 | H37: =H34-H35-H36 -> 2194.159 | I37: =I34-I35-I36 -> 1727.375 | J37: =J34-J35-J36 -> 1781.748 | K37: =K34-K35-K36 -> 1964.43 | L37: =L34-L35-L36 -> 2138.9429 | M37: =M34-M35-M36 -> 1676.6932 | ... Q37: =Q34-Q35-Q36 -> 1825.8382 | S37: =SUM(F37:I37) -> 7356.864 | T37: =SUM(J37:M37) -> 7561.8141 | U37: =SUM(N37:Q37) -> 7935.7132
B39: Base case: our view
B40: Occupancy change y/y (pts): consensus case + KPI 2 (2027) | L40: -2.4 | M40: -2.8 | N40: =N13+'KPI 2 Booking Build'!F26 -> -2 | O40: =O13+'KPI 2 Booking Build'!G26 -> -0.5 | P40: =P13+'KPI 2 Booking Build'!H26 -> 0.5 | Q40: =Q13+'KPI 2 Booking Build'!I26 -> 1
B41: Underlying price on sold cabins (2H26 calibrated to guidance; 2027 = consensus case) | L41: -0.1055 | M41: -0.043303856 | N41: =N14 -> 0.005 | O41: =O14 -> 0.005 | P41: =P14 -> 0.005 | Q41: =Q14 -> 0.005
B42: Thesis 1: fare cuts on unsold cabins (KPI 1 build) | L42: ='KPI 1 Price Build'!D39 -> 0 | M42: ='KPI 1 Price Build'!E39 -> -0.032896144 | N42: ='KPI 1 Price Build'!F39 -> -0.033407702 | O42: ='KPI 1 Price Build'!G39 -> -0.028735886 | P42: ='KPI 1 Price Build'!H39 -> -0.0028358453 | Q42: ='KPI 1 Price Build'!I39 -> -0.0060902232
B43: Brand / new-ship mix effect on ticket price | L43: 0.005 | M43: 0.005 | N43: 0.01 | O43: 0.01 | P43: 0.01 | Q43: 0.01
B44: Thesis 2: late discounts on the booking shortfall (KPI 2 build) | L44: ='KPI 2 Booking Build'!D32 -> 0 | M44: ='KPI 2 Booking Build'!E32 -> 0 | N44: ='KPI 2 Booking Build'!F32 -> 0 | O44: ='KPI 2 Booking Build'!G32 -> 0 | P44: ='KPI 2 Booking Build'!H32 -> -0.0065792288 | Q44: ='KPI 2 Booking Build'!I32 -> -0.0065792288
...

Sheet KPI 1 Price Build
B2: KPI 1 Price Build (Thesis 1): fare cuts on unsold cabins -> ticket revenue per passenger day
B3: Thesis 1: NCL is cutting prices to fill Caribbean ships because it is losing share there. The fare panel measures the cuts; this sheet applies them only to cabins NCL still has to sell, by brand and region. Output (section E) feeds the Net Yield Build.
C5: Logic / source | D5: 3Q26E | E5: 4Q26E | F5: 1Q27E | G5: 2Q27E | H5: 3Q27E | I5: 4Q27E
B6: Fare-panel sailing window | D6: sailed | E6: Q4 2026 | F6: 1H 2027 | G6: 1H 2027 | H6: 2H 2027 | I6: 2H 2027
B7: Months from Oct 2, 2026 to mid-quarter sailing | D7: 0 | E7: 1.5 | F7: 4.5 | G7: 7.5 | H7: 10.5 | I7: 13.5
B9: A. Where NCLH capacity sails
B10: NCLH Caribbean share of capacity (deployment estimate) | C10: Team estimate from published itinerary schedules | D10: 0.18 | E10: 0.5 | F10: 0.62 | G10: 0.38 | H10: 0.2 | I10: 0.48
B11: Oceania + Regent share of NCLH capacity | C11: Fleet Qtr Build row 11 | D11: ='Fleet Qtr Build'!J11 -> 0.1558885 | E11: ='Fleet Qtr Build'!K11 -> 0.1602809 | F11: ='Fleet Qtr Build'!L11 -> 0.16954423 | G11: ='Fleet Qtr Build'!M11 -> 0.16673483 | H11: ='Fleet Qtr Build'!N11 -> 0.17116326 | I11: ='Fleet Qtr Build'!O11 -> 0.17527449
B12: Oceania + Regent: Caribbean share of their itineraries | C12: Fare Panel A: itinerary counts in the window | D12: =IF(D$6="sailed",0,(SUMIFS('Fare Panel'!$E$8:$E$114,'Fare Panel'!$B$8:$B$114,"Oceania",'Fare Panel'!$C$8:$C$114,"Caribbean/Bahamas",'Fare Panel'!$D$8:$D$114,D$6)+SUMIFS('Fare Panel'!$E$8:$E$114,'Fare Panel'!$B$8:$B$114,"Regent Seven Seas",'Fare Panel'!$C$8:$C$114,"Caribbean/Bahamas",'Fare Panel'!$D$8:$D$114,D$6))/(SUMIFS('Fare Panel'!$E$8:$E$114,'Fare Panel'!$B$8:$B$114,"Oceania",'Fare Panel'!$D$8:$D$114,D$6)+SUMIFS('Fare Panel'!$E$8:$E$114,'Fare Panel'!$B$8:$B$114,"Regent Seven Seas",'Fare Panel'!$D$8:$D$114,D$6))) -> 0 | E12: =IF(E$6="sailed",0,(SUMIFS('Fare Panel'!$E$8:$E$114,'Fare Panel'!$B$8:$B$114,"Oceania",'Fare Panel'!$C$8:$C$114,"Caribbean/Bahamas",'Fare Panel'!$D$8:$D$114,E$6)+SUMIFS('Fare Panel'!$E$8:$E$114,'Fare Panel'!$B$8:$B$114,"Regent Seven Seas",'Fare Panel'!$C$8:$C$114,"Caribbean/Bahamas",'Fare Panel'!$D$8:$D$114,E$6))/(SUMIFS('Fare Panel'!$E$8:$E$114,'Fare Panel'!$B$8:$B$114,"Oceania",'Fare Panel'!$D$8:$D$114,E$6)+SUMIFS('Fare Panel'!$E$8:$E$114,'Fare Panel'!$B$8:$B$114,"Regent Seven Seas",'Fare Panel'!$D$8:$D$114,E$6))) -> 0.36363636 | F12: =IF(F$6="sailed",0,(SUMIFS('Fare Panel'!$E$8:$E$114,'Fare Panel'!$B$8:$B$114,"Oceania",'Fare Panel'!$C$8:$C$114,"Caribbean/Bahamas",'Fare Panel'!$D$8:$D$114,F$6)+SUMIFS('Fare Panel'!$E$8:$E$114,'Fare Panel'!$B$8:$B$114,"Regent Seven Seas",'Fare Panel'!$C$8:$C$114,"Caribbean/Bahamas",'Fare Panel'!$D$8:$D$114,F$6))/(SUMIFS('Fare Panel'!$E$8:$E$114,'Fare Panel'!$B$8:$B$114,"Oceania",'Fare Panel'!$D$8:$D$114,F$6)+SUMIFS('Fare Panel'!$E$8:$E$114,'Fare Panel'!$B$8:$B$114,"Regent Seven Seas",'Fare Panel'!$D$8:$D$114,F$6))) -> 0.052631579 | G12: =IF(G$6="sailed",0,(SUMIFS('Fare Panel'!$E$8:$E$114,'Fare Panel'!$B$8:$B$114,"Oceania",'Fare Panel'!$C$8:$C$114,"Caribbean/Bahamas",'Fare Panel'!$D$8:$D$114,G$6)+SUMIFS('Fare Panel'!$E$8:$E$114,'Fare Panel'!$B$8:$B$114,"Regent Seven Seas",'Fare Panel'!$C$8:$C$114,"Caribbean/Bahamas",'Fare Panel'!$D$8:$D$114,G$6))/(SUMIFS('Fare Panel'!$E$8:$E$114,'Fare Panel'!$B$8:$B$114,"Oceania",'Fare Panel'!$D$8:$D$114,G$6)+SUMIFS('Fare Panel'!$E$8:$E$114,'Fare Panel'!$B$8:$B$114,"Regent Seven Seas",'Fare Panel'!$D$8:$D$114,G$6))) -> 0.052631579 | H12: =IF(H$6="sailed",0,(SUMIFS('Fare Panel'!$E$8:$E$114,'Fare Panel'!$B$8:$B$114,"Oceania",'Fare Panel'!$C$8:$C$114,"Caribbean/Bahamas",'Fare Panel'!$D$8:$D$114,H$6)+SUMIFS('Fare Panel'!$E$8:$E$114,'Fare Panel'!$B$8:$B$114,"Regent Seven Seas",'Fare Panel'!$C$8:$C$114,"Caribbean/Bahamas",'Fare Panel'!$D$8:$D$114,H$6))/(SUMIFS('Fare Panel'!$E$8:$E$114,'Fare Panel'!$B$8:$B$114,"Oceania",'Fare Panel'!$D$8:$D$114,H$6)+SUMIFS('Fare Panel'!$E$8:$E$114,'Fare Panel'!$B$8:$B$114,"Regent Seven Seas",'Fare Panel'!$D$8:$D$114,H$6))) -> 0.11111111 | I12: =IF(I$6="sailed",0,(SUMIFS('Fare Panel'!$E$8:$E$114,'Fare Panel'!$B$8:$B$114,"Oceania",'Fare Panel'!$C$8:$C$114,"Caribbean/Bahamas",'Fare Panel'!$D$8:$D$114,I$6)+SUMIFS('Fare Panel'!$E$8:$E$114,'Fare Panel'!$B$8:$B$114,"Regent Seven Seas",'Fare Panel'!$C$8:$C$114,"Caribbean/Bahamas",'Fare Panel'!$D$8:$D$114,I$6))/(SUMIFS('Fare Panel'!$E$8:$E$114,'Fare Panel'!$B$8:$B$114,"Oceania",'Fare Panel'!$D$8:$D$114,I$6)+SUMIFS('Fare Panel'!$E$8:$E$114,'Fare Panel'!$B$8:$B$114,"Regent Seven Seas",'Fare Panel'!$D$8:$D$114,I$6))) -> 0.11111111
B13: NCL brand: Caribbean share of its capacity | C13: (NCLH share - luxury share x luxury Caribbean share) / NCL share | D13: =MIN(1,(D10-D11*D12)/(1-D11)) -> 0.21324197 | E13: =MIN(1,(E10-E11*E12)/(1-E11)) -> 0.52602833 | F13: =MIN(1,(F10-F11*F12)/(1-F11)) -> 0.73583283 | G13: =MIN(1,(G10-G11*G12)/(1-G11)) -> 0.44550582 | H13: =MIN(1,(H10-H11*H12)/(1-H11)) -> 0.21835646 | I13: =MIN(1,(I10-I11*I12)/(1-I11)) -> 0.55839798
B15: B. Observed fare change: median vs. each itinerary's own 90-day average (Oct 2, 2026)
B16: NCL: Caribbean | C16: Fare Panel A | D16: =IF(D$6="sailed",0,SUMIFS('Fare Panel'!$F$8:$F$114,'Fare Panel'!$B$8:$B$114,"Norwegian",'Fare Panel'!$C$8:$C$114,"Caribbean/Bahamas",'Fare Panel'!$D$8:$D$114,D$6)) -> 0 | E16: =IF(E$6="sailed",0,SUMIFS('Fare Panel'!$F$8:$F$114,'Fare Panel'!$B$8:$B$114,"Norwegian",'Fare Panel'!$C$8:$C$114,"Caribbean/Bahamas",'Fare Panel'!$D$8:$D$114,E$6)) -> -0.36 | F16: =IF(F$6="sailed",0,SUMIFS('Fare Panel'!$F$8:$F$114,'Fare Panel'!$B$8:$B$114,"Norwegian",'Fare Panel'!$C$8:$C$114,"Caribbean/Bahamas",'Fare Panel'!$D$8:$D$114,F$6)) -> -0.145 | G16: =IF(G$6="sailed",0,SUMIFS('Fare Panel'!$F$8:$F$114,'Fare Panel'!$B$8:$B$114,"Norwegian",'Fare Panel'!$C$8:$C$114,"Caribbean/Bahamas",'Fare Panel'!$D$8:$D$114,G$6)) -> -0.145 | H16: =IF(H$6="sailed",0,SUMIFS('Fare Panel'!$F$8:$F$114,'Fare Panel'!$B$8:$B$114,"Norwegian",'Fare Panel'!$C$8:$C$114,"Caribbean/Bahamas",'Fare Panel'!$D$8:$D$114,H$6)) -> -0.02 | I16: =IF(I$6="sailed",0,SUMIFS('Fare Panel'!$F$8:$F$114,'Fare Panel'!$B$8:$B$114,"Norwegian",'Fare Panel'!$C$8:$C$114,"Caribbean/Bahamas",'Fare Panel'!$D$8:$D$114,I$6)) -> -0.02
